Workbook
Name _bareme: Barême!$B$3:$C$15
Name _etudiant_1: Identification!$A$18
Name _etudiant_2: Identification!$A$19
Name _etudiant_3: Identification!$A$20
Name _etudiant_4: Identification!$A$21
Name _etudiant_5: Identification!$A$22
Name _etudiant_6: Identification!$A$23
Name _superviseur_1: Identification!$B$8
Name _superviseur_2: Identification!$B$9
Name _superviseur_3: Identification!$B$10
Name _superviseur_4: Identification!$B$11

Sheet Identification
A1: LOG795 : Projet de fin d’études en génie logiciel | H1: Légende
A2: GTI795 : Projet de fin d’études en génie des technologies de l’information | I2: À remplir par les étudiants ou superviseur(s)
I3: Ne pas déplacer (mais changer la description au besoin), évaluations liées aux Qualités et Indicateurs
I4: Calcul automatique ne pas toucher la cellule
A5: Numéro d'équipe | I5: À négocier entre professeur et étudiants
A6: Titre du projet | I6: À remplir par le professeur
A8: Superviseur 1
A9: Superviseur 2
A10: Superviseur 3
A11: Superviseur 4
A16: IDENTIFICATION
A17: Prénom NOM | B17: Code permanent | C17: Note | D17: Pénalités | E17: Note finale | F17: Cote
A18: Étudiant 1 | C18: =IF(_etudiant_1="","",Évaluation!$N40) -> #DIV/0! | E18: =IF(_etudiant_1="","",C18-D18) -> #DIV/0! | F18: =IF(A18="","",VLOOKUP(E18,_bareme,2,TRUE)) -> #DIV/0!
A19: Étudiant 2 | C19: =IF(_etudiant_2="","",Évaluation!$N41) -> #DIV/0! | E19: =IF(_etudiant_2="","",C19-D19) -> #DIV/0! | F19: =IF(A19="","",VLOOKUP(E19,_bareme,2,TRUE)) -> #DIV/0!
A20: Étudiant 3 | C20: =IF(_etudiant_3="","",Évaluation!$N42) -> #DIV/0! | E20: =IF(_etudiant_3="","",C20-D20) -> #DIV/0! | F20: =IF(A20="","",VLOOKUP(E20,_bareme,2,TRUE)) -> #DIV/0!
A21: Étudiant 4 | C21: =IF(_etudiant_4="","",Évaluation!$N43) -> #DIV/0! | E21: =IF(_etudiant_4="","",C21-D21) -> #DIV/0! | F21: =IF(A21="","",VLOOKUP(E21,_bareme,2,TRUE)) -> #DIV/0!
C22: =IF(_etudiant_5="","",Évaluation!$N44) | E22: =IF(_etudiant_5="","",C22-D22) | F22: =IF(A22="","",VLOOKUP(E22,_bareme,2,TRUE))
C23: =IF(_etudiant_6="","",Évaluation!$N45) | E23: =IF(_etudiant_6="","",C23-D23) | F23: =IF(A23="","",VLOOKUP(E23,_bareme,2,TRUE))

Sheet Évaluation
A1: LOG795 : Projet de fin d’études en génie logiciel
A2: GTI795 : Projet de fin d’études en génie des technologies de l’information | L2: Légende
A3: Voir le plan du cours pour les explications (Éléments d'évaluation obligatoires et optionnels) | M3: À remplir par les étudiants
B4: Éléments techniques (entre 70 et 80 points) | C4: % | D4: Résultats | E4: Gestion de projet (entre 5 et 10 points) | F4: % | G4: Résultats | H4: Professionalisme (entre 15 et 20 points) | I4: % | J4: Résultats | M4: Ne pas déplacer (mais changer la description au besoin), évaluations liées aux Qualités et Indicateurs
M5: Calcul automatique ne pas toucher la cellule
A6: ÉLÉMENTS OBLIGATOIRES Tous les éléments obligatoires sont sommatifs. | B6: Rapport final (Q7-I1) | C6: 40 | E6: Plan de projet (problématique) (Q4-I1) | F6: 2 | H6: Communication | I6: 5 | M6: À négocier entre professeur et étudiants
E7: Date: 2e semaine de la session | M7: À remplir par le professeur
B8: Activité: Analyse des diverses solutions techniques (Q4-I2) | C8: 15 | E8: Plan de projet (le reste) (Q11-I1) | F8: 2 | H8: Travail en équipe Q6-I4 (évaluation par les pairs) | J8: ='Évaluation par les pairs'!H13/100*10 -> #DIV/0!
E9: Date: 2e semaine de la session
E10: Q9-I1 du Plan de projet | F10: 3 | H10: Présentation orale (audience) | I10: 10
E12: Réunions (Ordres du jour et compte rendus) | F12: 1
A14: ÉLÉMENTS OPTIONNELS Effacer ou barrer les éléments optionnels suggérés s’ils ne s’appliquent pas. Si l’élément est formatif, indiquez une pondération de 0%. Au besoin, ajouter des éléments optionnels en indiquant la date et la valeur en % si l’élément est sommatif. | B14: Activité: | E14: Activité: Évaluation du Kanban | F14: 2 | H14: Activité:
B15: Date: | E15: Date: | H15: Date:
B16: Activité: Conception | C16: 5 | E16: Activité: | H16: Activité | L16: COMMENTAIRES
B17: Date: | E17: Date: | H17: Date:
B18: Activité: Guide utilisateur | C18: 5 | E18: Activité: | H18: Activité
B19: Date: | E19: Date: | H19: Date:
B20: Activité: Démo vidéo (live) | C20: 5 | E20: Activité | H20: Activité
B21: Date: 2 Décembre 2025 | E21: Date: | H21: Date:
B22: Activité: Qualité du code | C22: 5 | E22: Activité | H22: Activité
B23: Date: | E23: Date: | H23: Date:
B24: Activité: | E24: Activité | H24: Activité
B25: Date: | E25: Date: | H25: Date:
B26: Activité: | E26: Activité | H26: Activité
B27: Date: | E27: Date: | H27: Date:
B28: Activité: | E28: Activité | H28: Activité
B29: Date: | E29: Date: | H29: Date:
B30: Activité: | E30: Activité | H30: Activité
B31: Date: | E31: Date: | H31: Date:
B32: Activité: | E32: Activité | H32: Activité
B33: Date: | E33: Date: | H33: Date:
B34: Activité: | E34: Activité: | H34: Activité
B35: Date: | E35: Date: | H35: Date: | K35: TOTAL
A36: TOTAL | C36: =SUM(C6:C35) -> 75 | D36: =SUM(D6:D35) -> 0 | F36: =SUM(F6:F35) -> 10 | G36: =SUM(G6:G35) -> 0 | I36: =SUM(I6:I35) -> 15 | J36: =SUM(J6:J35) -> #DIV/0! | K36: =J36+G36+D36 -> #DIV/0!
K37: =I36+F36+C36 -> 100
A39: ÉTUDIANTS | E39: PROFESSEURS | L39: Prénom NOM | M39: Facteur | N39: Note finale
A40: Prénom NOM | B40: Signature | E40: Prénom NOM | F40: Signature | L40: =IF(_etudiant_1="","",_etudiant_1) -> Étudiant 1 | M40: =IF(_etudiant_1="","",'Évaluation par les pairs'!$I7) -> 1 | N40: =IF(_etudiant_1="","",MIN(100,($D$36+$G$36+$J$36)*M40)) -> #DIV/0!
A41: =IF(_etudiant_1="","",_etudiant_1) -> Étudiant 1 | B41: Nicolas Paquette | E41: =IF(_superviseur_1="","",_superviseur_1) | L41: =IF(_etudiant_2="","",_etudiant_2) -> Étudiant 2 | M41: =IF(_etudiant_2="","",'Évaluation par les pairs'!$I8) -> 1 | N41: =IF(_etudiant_2="","",MIN(100,($D$36+$G$36+$J$36)*M41)) -> #DIV/0!
A42: =IF(_etudiant_2="","",_etudiant_2) -> Étudiant 2 | B42: Ulysse Corbeil | E42: =IF(_superviseur_2="","",_superviseur_2) | L42: =IF(_etudiant_3="","",_etudiant_3) -> Étudiant 3 | M42: =IF(_etudiant_3="","",'Évaluation par les pairs'!$I9) -> 1 | N42: =IF(_etudiant_3="","",MIN(100,($D$36+$G$36+$J$36)*M42)) -> #DIV/0!
A43: =IF(_etudiant_3="","",_etudiant_3) -> Étudiant 3 | B43: Vincent Fleury | E43: =IF(_superviseur_3="","",_superviseur_3) | L43: =IF(_etudiant_4="","",_etudiant_4) -> Étudiant 4 | M43: =IF(_etudiant_4="","",'Évaluation par les pairs'!$I10) -> 1 | N43: =IF(_etudiant_4="","",MIN(100,($D$36+$G$36+$J$36)*M43)) -> #DIV/0!
...

Sheet Évaluation par les pairs
A1: LOG795 : Projet de fin d’études en génie logiciel
A2: GTI795 : Projet de fin d’études en génie des technologies de l’information
A5: ÉVALUATION PAR LES PAIRS
A6: Prénom NOM | B6: =IF(_etudiant_1="","","Evaluation 1") -> Evaluation 1 | C6: =IF(_etudiant_2="","","Evaluation 2") -> Evaluation 2 | D6: =IF(_etudiant_3="","","Evaluation 3") -> Evaluation 3 | E6: =IF(_etudiant_4="","","Evaluation 4") -> Evaluation 4 | F6: =IF(_etudiant_5="","","Evaluation 5") | G6: =IF(_etudiant_6="","","Evaluation 6") | H6: Evaluation Moyenne | I6: Facteur
A7: =IF(_etudiant_1="","",_etudiant_1) -> Étudiant 1 | H7: =IF(_etudiant_1="","",AVERAGE(B7:G7)) -> #DIV/0! | I7: =IF(_etudiant_1="","",IF(SUMPRODUCT(--(B7:G7<>""))=0,1,AVERAGE(B7:G7)/AVERAGE($B$7:$G$12))) -> 1
A8: =IF(_etudiant_2="","",_etudiant_2) -> Étudiant 2 | H8: =IF(_etudiant_2="","",AVERAGE(B8:G8)) -> #DIV/0! | I8: =IF(_etudiant_2="","",IF(SUMPRODUCT(--(B8:G8<>""))=0,1,AVERAGE(B8:G8)/AVERAGE($B$7:$G$12))) -> 1
A9: =IF(_etudiant_3="","",_etudiant_3) -> Étudiant 3 | H9: =IF(_etudiant_3="","",AVERAGE(B9:G9)) -> #DIV/0! | I9: =IF(_etudiant_3="","",IF(SUMPRODUCT(--(B9:G9<>""))=0,1,AVERAGE(B9:G9)/AVERAGE($B$7:$G$12))) -> 1
A10: =IF(_etudiant_4="","",_etudiant_4) -> Étudiant 4 | H10: =IF(_etudiant_4="","",AVERAGE(B10:G10)) -> #DIV/0! | I10: =IF(_etudiant_4="","",IF(SUMPRODUCT(--(B10:G10<>""))=0,1,AVERAGE(B10:G10)/AVERAGE($B$7:$G$12))) -> 1
A11: =IF(_etudiant_5="","",_etudiant_5) | H11: =IF(_etudiant_5="","",AVERAGE(B11:G11)) | I11: =IF(_etudiant_5="","",IF(SUMPRODUCT(--(B11:G11<>""))=0,1,AVERAGE(B11:G11)/AVERAGE($B$7:$G$12)))
A12: =IF(_etudiant_6="","",_etudiant_6) | H12: =IF(_etudiant_6="","",AVERAGE(B12:G12)) | I12: =IF(_etudiant_6="","",IF(SUMPRODUCT(--(B12:G12<>""))=0,1,AVERAGE(B12:G12)/AVERAGE($B$7:$G$12)))
A13: =IF(_etudiant_6="","",_etudiant_6) | B13: =IF(_etudiant_1="","",AVERAGE(B7:B12)) -> #DIV/0! | C13: =IF(_etudiant_2="","",AVERAGE(C7:C12)) -> #DIV/0! | D13: =IF(_etudiant_3="","",AVERAGE(D7:D12)) -> #DIV/0! | E13: =IF(_etudiant_4="","",AVERAGE(E7:E12)) -> #DIV/0! | F13: =IF(_etudiant_5="","",AVERAGE(F7:F12)) | G13: =IF(_etudiant_6="","",AVERAGE(G7:G12)) | H13: =AVERAGE(B13:G13) -> #DIV/0!
A16: Critéres d'évaluation | B16: 70 | C16: Très en dessous des attentes
B17: 80 | C17: Significativement en dessous des attentes
B18: 82 | C18: Un peu en dessous des attentes
B19: 85 | C19: Rencontre les attentes
B20: 87 | C20: Dépasse un peu les attentes
B21: 90 | C21: Dépasse largement les attentes

Sheet Barême
A1: Cette grille est utilisée pour attribuer automatiquement les notes littérales.
B3: Points | C3: Cote
B4: 0 | C4: E
B5: 50 | C5: D
B6: 61 | C6: D+
B7: 65 | C7: C-
B8: 68 | C8: C
B9: 72 | C9: C+
B10: 75 | C10: B-
B11: 78 | C11: B
B12: 81 | C12: B+
B13: 85 | C13: A-
B14: 88 | C14: A
B15: 91 | C15: A+

Sheet Indicateurs
A1: Indicateurs | B1: Description des indicateurs | D1: Note (sur 5) | E1: Source | F1: Source selon contrat
A2: Q4-i1 Formulation du problème | B2: Formuler un problème d’ingénierie ouvert en tenant compte des besoins et des contraintes telles que les risques pour la santé et la sécurité publiques, les aspects législatifs et règlementaires, ainsi que des incidences économiques, environnementales, culturelles et sociales. | D2: =Évaluation!G6/Évaluation!F6*5 -> 0 | E2: Plan de projet (problématique) | F2: =Évaluation!E6 -> Plan de projet (problématique) (Q4-I1)
A3: Q4-I2 Formuler les solutions | B3: Formuler diverses solutions pour un problème de génie des technologies de l’information complexe | D3: =Évaluation!D8/Évaluation!C8*5 -> 0 | E3: Analyse des solutions | F3: =Évaluation!B10 -> 0
A4: Q6-I4 Évaluation de l'équipe | B4: Évaluer le fonctionnement de l’équipe par rapport aux objectifs établis et en regard de l’accord de collaboration. | C4: =IF(_etudiant_1="","",_etudiant_1) -> Étudiant 1 | D4: =IF(_etudiant_1="","",'Évaluation par les pairs'!H7/100*5) -> #DIV/0! | E4: Évaluation par les pairs | F4: =Évaluation!H8 -> Travail en équipe Q6-I4 (évaluation par les pairs)
C5: =IF(_etudiant_2="","",_etudiant_2) -> Étudiant 2 | D5: =IF(_etudiant_2="","",'Évaluation par les pairs'!H8/100*5) -> #DIV/0!
C6: =IF(_etudiant_3="","",_etudiant_3) -> Étudiant 3 | D6: =IF(_etudiant_3="","",'Évaluation par les pairs'!H9/100*5) -> #DIV/0!
C7: =IF(_etudiant_4="","",_etudiant_4) -> Étudiant 4 | D7: =IF(_etudiant_4="","",'Évaluation par les pairs'!H10/100*5) -> #DIV/0!
C8: =IF(_etudiant_5="","",_etudiant_5) | D8: =IF(_etudiant_5="","",'Évaluation par les pairs'!H11/100*5)
C9: =IF(_etudiant_6="","",_etudiant_6) | D9: =IF(_etudiant_6="","",'Évaluation par les pairs'!H12/100*5)
A10: Q7-I1 - Rédaction | B10: Rédiger de façon professionnelle des rapports techniques documentant efficacement un travail d’ingénierie en utilisant différentes formes de langage (naturel, graphique, mathématique, etc.). | D10: =Évaluation!D6/Évaluation!C6*5 -> 0 | E10: Rapport final | F10: =Évaluation!B6 -> Rapport final (Q7-I1)
A11: Q9-I1 - Interaction sociaux | B11: Tenir compte des enjeux économiques et sociaux lors de l’évaluation ou la réalisation de projets d’ingénierie. | D11: =Évaluation!G10/Évaluation!F10*5 -> 0 | E11: Justifier dans le plan de projet | F11: =Évaluation!E10 -> Q9-I1 du Plan de projet
A12: Q11-I1 - Définir un projet | B12: Définir un projet : définir les objectifs, les spécifications et rédiger un cahier des charges. | D12: =Évaluation!G8/Évaluation!F8*5 -> 0 | E12: Plan de projet | F12: =Évaluation!E8 -> Plan de projet (le reste) (Q11-I1)
